<sdf version='1.9'>
  <model name='Montaj1'>
    <link name='base_link'>
      <inertial>
        <pose>-0.0013654 -0.00019199 -0.0012332 0 0 0</pose>
        <mass>0.014123</mass>
        <inertia>
          <ixx>1.4814999999999999e-06</ixx>
          <ixy>-1.6467e-22</ixy>
          <ixz>8.7230000000000001e-25</ixz>
          <iyy>2.2071999999999998e-06</iyy>
          <iyz>7.5505000000000004e-23</iyz>
          <izz>3.4597000000000001e-06</izz>
        </inertia>
      </inertial>
      <collision name='base_link_collision'>
        <pose>0 0 0 0 0 0</pose>
        <geometry>
          <mesh>
            <scale>1 1 1</scale>
            <uri>model://urdf/Montaj1/meshes/base_link.STL</uri>
          </mesh>
        </geometry>
      </collision>
      <visual name='base_link_visual'>
        <pose>0 0 0 0 0 0</pose>
        <geometry>
          <mesh>
            <scale>1 1 1</scale>
            <uri>model://urdf/Montaj1/meshes/base_link.STL</uri>
          </mesh>
        </geometry>
        <material>
          <diffuse>0.9902 1 1 1</diffuse>
          <ambient>0.9902 1 1 1</ambient>
        </material>
      </visual>
    </link>
    <joint name='wheelleft_joint' type='revolute'>
      <pose relative_to='base_link'>-0.0013654 -0.027601 -0.0012332 -3.141585307179587 0 0</pose>
      <parent>base_link</parent>
      <child>wheelleft_link</child>
      <axis>
        <xyz>0 1 0</xyz>
        <limit>
          <lower>-10000000000000000</lower>
          <upper>10000000000000000</upper>
        </limit>
        <dynamics>
          <spring_reference>0</spring_reference>
          <spring_stiffness>0</spring_stiffness>
        </dynamics>
      </axis>
    </joint>
    <link name='wheelleft_link'>
      <pose relative_to='wheelleft_joint'>0 0 0 0 0 0</pose>
      <inertial>
        <pose>-1.4095e-17 0.005 -3.2526e-18 0 0 0</pose>
        <mass>0.041633999999999997</mass>
        <inertia>
          <ixx>1.9805000000000001e-05</ixx>
          <ixy>-2.268e-38</ixy>
          <ixz>4.4412000000000003e-39</ixz>
          <iyy>3.8915000000000003e-05</iyy>
          <iyz>1.2785e-21</iyz>
          <izz>1.9805000000000001e-05</izz>
        </inertia>
      </inertial>
      <collision name='wheelleft_link_collision'>
        <pose>0 0 0 0 0 0</pose>
        <geometry>
          <mesh>
            <scale>1 1 1</scale>
            <uri>model://urdf/Montaj1/meshes/wheelleft_link.STL</uri>
          </mesh>
        </geometry>
      </collision>
      <visual name='wheelleft_link_visual'>
        <pose>0 0 0 0 0 0</pose>
        <geometry>
          <mesh>
            <scale>1 1 1</scale>
            <uri>model://urdf/Montaj1/meshes/wheelleft_link.STL</uri>
          </mesh>
        </geometry>
        <material>
          <diffuse>0.9902 1 1 1</diffuse>
          <ambient>0.9902 1 1 1</ambient>
        </material>
      </visual>
    </link>
  </model>
</sdf>
