<!-- <?xml version="1.0" encoding="utf-8"?> -->
<!-- This URDF was automatically created by SolidWorks to URDF Exporter! Originally created by Stephen Brawner (brawner@gmail.com) 
     Commit Version: 1.6.0-4-g7f85cfe  Build Version: 1.6.7995.38578
     For more information, please see http://wiki.ros.org/sw_urdf_exporter -->
<robot
  name="Montaj1">
  <link
    name="base_link">
    <inertial>
      <origin
        xyz="-0.0013654 -0.00019199 -0.0012332"
        rpy="0 0 0" />
      <mass
        value="0.014123" />
      <inertia
        ixx="1.4815E-06"
        ixy="-1.6467E-22"
        ixz="8.723E-25"
        iyy="2.2072E-06"
        iyz="7.5505E-23"
        izz="3.4597E-06" />
    </inertial>
    <visual>
      <origin
        xyz="0 0 0"
        rpy="0 0 0" />
      <geometry>
        <mesh
          filename="package://urdf/Montaj1/meshes/base_link.STL" />
      </geometry>
      <material
        name="">
        <color
          rgba="0.79216 0.81961 0.93333 1" />
      </material>
    </visual>
    <collision>
      <origin
        xyz="0 0 0"
        rpy="0 0 0" />
      <geometry>
        <mesh
          filename="package://urdf/Montaj1/meshes/base_link.STL" />
      </geometry>
    </collision>
  </link>
  <link
    name="wheelleft_link">
    <inertial>
      <origin
        xyz="-1.4095E-17 0.005 -3.2526E-18"
        rpy="0 0 0" />
      <mass
        value="0.041634" />
      <inertia
        ixx="1.9805E-05"
        ixy="-2.268E-38"
        ixz="4.4412E-39"
        iyy="3.8915E-05"
        iyz="1.2785E-21"
        izz="1.9805E-05" />
    </inertial>
    <visual>
      <origin
        xyz="0 0 0"
        rpy="0 0 0" />
      <geometry>
        <mesh
          filename="package://urdf/Montaj1/meshes/wheelleft_link.STL" />
      </geometry>
      <material
        name="">
        <color
          rgba="0.79216 0.81961 0.93333 1" />
      </material>
    </visual>
    <collision>
      <origin
        xyz="0 0 0"
        rpy="0 0 0" />
      <geometry>
        <mesh
          filename="package://urdf/Montaj1/meshes/wheelleft_link.STL" />
      </geometry>
    </collision>
  </link>
  <joint
    name="wheelleft_joint"
    type="continuous">
    <origin
      xyz="-0.0013654 -0.027601 -0.0012332"
      rpy="3.1416 0 0" />
    <parent
      link="base_link" />
    <child
      link="wheelleft_link" />
    <axis
      xyz="0 1 0" />
  </joint>
</robot>